Traceback (most recent call last):
  File "/Users/bhills/anaconda3/lib/python3.11/site-packages/jupyter_cache/executors/utils.py", line 58, in single_nb_execution
    executenb(
  File "/Users/bhills/anaconda3/lib/python3.11/site-packages/nbclient/client.py", line 1305, in execute
    return NotebookClient(nb=nb, resources=resources, km=km, **kwargs).execute()
           ^^^^^^^^^^^^^^^^^^^^^^^^^^^^^^^^^^^^^^^^^^^^^^^^^^^^^^^^^^^^^^^^^^^^^
  File "/Users/bhills/anaconda3/lib/python3.11/site-packages/jupyter_core/utils/__init__.py", line 173, in wrapped
    return loop.run_until_complete(inner)
           ^^^^^^^^^^^^^^^^^^^^^^^^^^^^^^
  File "/Users/bhills/anaconda3/lib/python3.11/asyncio/base_events.py", line 654, in run_until_complete
    return future.result()
           ^^^^^^^^^^^^^^^
  File "/Users/bhills/anaconda3/lib/python3.11/site-packages/nbclient/client.py", line 705, in async_execute
    await self.async_execute_cell(
  File "/Users/bhills/anaconda3/lib/python3.11/site-packages/nbclient/client.py", line 1058, in async_execute_cell
    await self._check_raise_for_error(cell, cell_index, exec_reply)
  File "/Users/bhills/anaconda3/lib/python3.11/site-packages/nbclient/client.py", line 914, in _check_raise_for_error
    raise CellExecutionError.from_cell_and_msg(cell, exec_reply_content)
nbclient.exceptions.CellExecutionError: An error occurred while executing the following cell:
------------------
from sar_functions import *
from supplemental import *

plt.figure()
plt.xlim(min(Xs),max(Xs))
C = matched_filter(r2p(R1_air))
plt.plot(Xs,C,'k--')
C = matched_filter(r2p(R1_ice))
plt.plot(Xs,C,'k-')
plt.text(0.03,0.8,'A',transform=ax1.transAxes,weight='bold',
        bbox=dict(facecolor='w', edgecolor='k',pad=2,lw=2))

ax2 = plt.subplot(212)
plt.xlim(min(Xs),max(Xs))
C = matched_filter(r2p(R2_air))
plt.plot(Xs,C,'--',c='indianred')
C = matched_filter(r2p(R2_ice))
plt.plot(Xs,C,'-',c='indianred')
plt.xlabel('Along-track distance (m)')
plt.ylabel('Ref. Waveform')
plt.text(0.03,0.8,'B',transform=ax2.transAxes,weight='bold',
        bbox=dict(facecolor='w', edgecolor='k',pad=2,lw=2))
------------------

----- stderr -----
/Users/bhills/anaconda3/lib/python3.11/site-packages/matplotlib/cbook.py:1699: ComplexWarning: Casting complex values to real discards the imaginary part
  return math.isfinite(val)
/Users/bhills/anaconda3/lib/python3.11/site-packages/matplotlib/cbook.py:1345: ComplexWarning: Casting complex values to real discards the imaginary part
  return np.asarray(x, float)
------------------

[0;31m---------------------------------------------------------------------------[0m
[0;31mNameError[0m                                 Traceback (most recent call last)
Cell [0;32mIn[5], line 10[0m
[1;32m      8[0m C [38;5;241m=[39m matched_filter(r2p(R1_ice))
[1;32m      9[0m plt[38;5;241m.[39mplot(Xs,C,[38;5;124m'[39m[38;5;124mk-[39m[38;5;124m'[39m)
[0;32m---> 10[0m plt[38;5;241m.[39mtext([38;5;241m0.03[39m,[38;5;241m0.8[39m,[38;5;124m'[39m[38;5;124mA[39m[38;5;124m'[39m,transform[38;5;241m=[39max1[38;5;241m.[39mtransAxes,weight[38;5;241m=[39m[38;5;124m'[39m[38;5;124mbold[39m[38;5;124m'[39m,
[1;32m     11[0m         bbox[38;5;241m=[39m[38;5;28mdict[39m(facecolor[38;5;241m=[39m[38;5;124m'[39m[38;5;124mw[39m[38;5;124m'[39m, edgecolor[38;5;241m=[39m[38;5;124m'[39m[38;5;124mk[39m[38;5;124m'[39m,pad[38;5;241m=[39m[38;5;241m2[39m,lw[38;5;241m=[39m[38;5;241m2[39m))
[1;32m     13[0m ax2 [38;5;241m=[39m plt[38;5;241m.[39msubplot([38;5;241m212[39m)
[1;32m     14[0m plt[38;5;241m.[39mxlim([38;5;28mmin[39m(Xs),[38;5;28mmax[39m(Xs))

[0;31mNameError[0m: name 'ax1' is not defined

